<?xml version="1.0" ?>
<!-- =================================================================================== -->
<!-- |    This document was autogenerated by xacro from scara_fixed_joints_classic.urdf.xacro | -->
<!-- |    EDITING THIS FILE BY HAND IS NOT RECOMMENDED                                 | -->
<!-- =================================================================================== -->
<robot name="scara_robot">
  <!-- Joint colors-->
  <gazebo reference="link1">
    <material>Gazebo/Green</material>
  </gazebo>
  <gazebo reference="link2">
    <material>Gazebo/Blue</material>
  </gazebo>
  <gazebo reference="link3">
    <material>Gazebo/Red</material>
  </gazebo>
  <gazebo reference="link4">
    <material>Gazebo/Purple</material>
  </gazebo>
  <!-- 
            Model setup 
    -->
  <!-- 
            Modeling the robot
    -->
  <link name="world_link"/>
  <joint name="world_to_base" type="fixed">
    <parent link="world_link"/>
    <child link="base_link"/>
    <origin rpy="0 0 0" xyz="0 0 0"/>
  </joint>
  <link name="base_link">
    <visual>
      <origin rpy="0 0 0" xyz="0 0 0.05"/>
      <geometry>
        <box size="0.5 0.5 0.1"/>
      </geometry>
    </visual>
    <collision>
      <origin rpy="0 0 0" xyz="0 0 0.05"/>
      <geometry>
        <box size="0.5 0.5 0.1"/>
      </geometry>
    </collision>
    <inertial>
      <origin rpy="0 0 0" xyz="0 0 0.05"/>
      <mass value="100"/>
      <inertia ixx="2.1666666666666665" ixy="0.0" ixz="0.0" iyy="2.1666666666666665" iyz="0.0" izz="4.166666666666666"/>
    </inertial>
  </link>
  <joint name="joint1" type="fixed">
    <parent link="base_link"/>
    <child link="link1"/>
    <origin rpy="0 0 0" xyz="0 0 0"/>
    <axis xyz="0 0 1"/>
    <!-- <limit lower="${joint1_lower}" upper="${joint1_upper}" effort="100" velocity="5.0" />
        <dynamics damping="0.1" friction="0.0"/> -->
  </joint>
  <link name="link1">
    <!-- Cylinder joint visual -->
    <visual>
      <origin rpy="0 0 0" xyz="0 0 0.25"/>
      <geometry>
        <cylinder length="0.5" radius="0.1"/>
      </geometry>
    </visual>
    <collision>
      <origin rpy="0 0 0" xyz="0 0 0.3"/>
      <geometry>
        <cylinder length="0.4" radius="0.1"/>
      </geometry>
    </collision>
    <inertial>
      <origin rpy="0 0 0" xyz="0 0 0.25"/>
      <mass value="1"/>
      <inertia ixx="0.023333333333333334" ixy="0.0" ixz="0.0" iyy="0.023333333333333334" iyz="0.0" izz="0.005000000000000001"/>
    </inertial>
    <!-- Arm visual -->
    <visual>
      <origin rpy="0 0 0" xyz="0.225 0 0.5"/>
      <geometry>
        <box size="0.45 0.1 0.1"/>
      </geometry>
    </visual>
    <collision>
      <origin rpy="0 0 0" xyz="0.225 0 0.5"/>
      <geometry>
        <box size="0.25 0.1 0.1"/>
      </geometry>
    </collision>
    <inertial>
      <origin rpy="0 0 0" xyz="0.225 0 0"/>
      <mass value="5"/>
      <inertia ixx="0.008333333333333335" ixy="0.0" ixz="0.0" iyy="0.08854166666666667" iyz="0.0" izz="0.08854166666666667"/>
    </inertial>
  </link>
  <link name="link2">
    <!-- Cylinder joint  visual -->
    <visual>
      <origin rpy="0 0 0" xyz="0 0 0"/>
      <geometry>
        <cylinder length="0.2" radius="0.1"/>
      </geometry>
      <material name="blue"/>
    </visual>
    <collision>
      <origin rpy="0 0 0" xyz="0 0 0"/>
      <geometry>
        <cylinder length="0.2" radius="0.1"/>
      </geometry>
    </collision>
    <inertial>
      <origin rpy="0 0 0" xyz="0 0 0"/>
      <mass value="1"/>
      <inertia ixx="0.005833333333333334" ixy="0.0" ixz="0.0" iyy="0.005833333333333334" iyz="0.0" izz="0.005000000000000001"/>
    </inertial>
    <!-- Arm visual -->
    <visual>
      <origin rpy="0 0 0" xyz="0.175 0 0"/>
      <geometry>
        <box size="0.35 0.1 0.1"/>
      </geometry>
    </visual>
    <collision>
      <origin rpy="0 0 0" xyz="0.175 0 0"/>
      <geometry>
        <box size="0.14999999999999997 0.1 0.1"/>
      </geometry>
    </collision>
    <inertial>
      <origin rpy="0 0 0" xyz="0.175 0 0"/>
      <mass value="4"/>
      <inertia ixx="0.006666666666666668" ixy="0.0" ixz="0.0" iyy="0.04416666666666666" iyz="0.0" izz="0.04416666666666666"/>
    </inertial>
  </link>
  <joint name="joint2" type="fixed">
    <parent link="link1"/>
    <child link="link2"/>
    <origin rpy="0 0 0" xyz="0.45 0 0.5"/>
    <!-- <limit lower="${joint2_lower}" upper="${joint2_upper}" effort="100" velocity="1.0" />
        <axis xyz="0 0 1" /> -->
  </joint>
  <link name="link3">
    <!-- Prismatic joint visual -->
    <visual>
      <origin rpy="0 0 0" xyz="0 0 0.1"/>
      <geometry>
        <box size="0.2 0.2 0.4"/>
      </geometry>
    </visual>
    <collision>
      <origin rpy="0 0 0" xyz="0 0 0.1"/>
      <geometry>
        <box size="0.2 0.2 0.4"/>
      </geometry>
    </collision>
    <inertial>
      <origin rpy="0 0 0" xyz="0 0 0.1"/>
      <mass value="2"/>
      <inertia ixx="0.03333333333333334" ixy="0.0" ixz="0.0" iyy="0.03333333333333334" iyz="0.0" izz="0.013333333333333336"/>
    </inertial>
  </link>
  <joint name="joint3" type="prismatic">
    <parent link="link2"/>
    <child link="link3"/>
    <origin rpy="0 0 0" xyz="0.35 0 0"/>
    <limit effort="1000" lower="0" upper="0.2" velocity="5"/>
    <axis xyz="0 0 -1"/>
    <dynamics damping="0.1" friction="0.0"/>
  </joint>
  <link name="link4">
    <!-- Cylinder visual -->
    <visual>
      <origin rpy="0 0 0" xyz="0 0 -0.15"/>
      <geometry>
        <cylinder length="0.3" radius="0.05"/>
      </geometry>
    </visual>
    <collision>
      <origin rpy="0 0 0" xyz="0 0 -0.09999999999999999"/>
      <geometry>
        <cylinder length="0.19999999999999998" radius="0.05"/>
      </geometry>
    </collision>
    <inertial>
      <origin rpy="0 0 0" xyz="0 0 -0.15"/>
      <mass value="0.5"/>
      <inertia ixx="0.0040625" ixy="0.0" ixz="0.0" iyy="0.0040625" iyz="0.0" izz="0.0006250000000000001"/>
    </inertial>
  </link>
  <joint name="joint4" type="fixed">
    <parent link="link3"/>
    <child link="link4"/>
    <origin rpy="3.141592653589793 0 0" xyz="0 0 -0.3"/>
    <axis xyz="0 0 1"/>
  </joint>
  <!-- 
            Gazebo Classic configuration
     -->
  <!--
        /gazebo/apply_joint_effort is provided by gazebo_ros API when Gazebo Classic
        is launched with gazebo_ros. This plugin publishes ROS joint states.
    -->
  <gazebo>
    <plugin filename="libgazebo_ros_joint_state_publisher.so" name="gazebo_ros_joint_state_publisher">
      <alwaysOn>true</alwaysOn>
      <update_rate>50.0</update_rate>
      <joint_name>joint3</joint_name>
    </plugin>
  </gazebo>
</robot>
