<?xml version="1.0" ?>
<!-- =================================================================================== -->
<!-- |    This document was autogenerated by xacro from myfirst.urdf.xacro             | -->
<!-- |    EDITING THIS FILE BY HAND IS NOT RECOMMENDED                                 | -->
<!-- =================================================================================== -->
<robot name="3dof_robot">
  <link name="world_link"/>
  <joint name="world_to_base" type="fixed">
    <parent link="world_link"/>
    <child link="base_link"/>
    <origin rpy="0 0 0" xyz="0 0 0"/>
  </joint>
  <link name="base_link">
    <visual>
      <origin rpy="0 0 0" xyz="0 0 0.05"/>
      <geometry>
        <box size="0.5 0.5 0.1"/>
      </geometry>
    </visual>
    <collision>
      <origin rpy="0 0 0" xyz="0 0 0.05"/>
      <geometry>
        <box size="0.5 0.5 0.1"/>
      </geometry>
    </collision>
    <inertial>
      <origin rpy="0 0 0" xyz="0 0 0.05"/>
      <mass value="10"/>
      <inertia ixx="0.21666666666666665" ixy="0.0" ixz="0.0" iyy="0.21666666666666665" iyz="0.0" izz="0.41666666666666663"/>
    </inertial>
  </link>
  <joint name="joint1" type="continuous">
    <parent link="base_link"/>
    <child link="link1"/>
    <origin rpy="0 0 0" xyz="0 0 0.1"/>
    <axis xyz="0 0 1"/>
  </joint>
  <link name="link1">
    <visual>
      <origin rpy="0 0 0" xyz="0 0 0.3"/>
      <geometry>
        <cylinder length="0.6" radius="0.1"/>
      </geometry>
    </visual>
    <collision>
      <origin rpy="0 0 0" xyz="0 0 0.3"/>
      <geometry>
        <cylinder length="0.6" radius="0.1"/>
      </geometry>
    </collision>
    <inertial>
      <origin rpy="0 0 0" xyz="0 0 0.3"/>
      <mass value="10"/>
      <inertia ixx="0.32499999999999996" ixy="0.0" ixz="0.0" iyy="0.32499999999999996" iyz="0.0" izz="0.05000000000000001"/>
    </inertial>
  </link>
  <!-- <link name="link2">
        <visual>
            <origin rpy="0 0 0" xyz="${link2_l/2} 0 0" />
            <geometry>
                <box size="${link2_l} ${link2_w} ${link2_h}" />
            </geometry>
        </visual>
        <collision>
            <origin rpy="0 0 0" xyz="${link2_l/2} 0 0" />
            <geometry>                
                <box size="${link2_l} ${link2_w} ${link2_h}" />
            </geometry>
        </collision>
        <xacro:inertial_box mass="0.01" x="${link2_l}" y="${link2_w}" z="${link2_h}">
            <origin rpy="0 0 0" xyz="${link2_l/2} 0 0" />
        </xacro:inertial_box>
    </link>

    <joint name="link1_to_link2" type="fixed">
        <parent link="link1" />
        <child link="link2" />
        <origin rpy="${link2_theta} 0 ${link2_alpha}" xyz="${link2_a} 0 ${link2_d}" />
    </joint>


    <link name="link3">
        <visual>
            <geometry>
                <cylinder length="${link3_l}" radius="${link3_r}" />
            </geometry>
        </visual>
        <collision>
            <geometry>
                <cylinder length="${link3_l}" radius="${link3_r}" />
            </geometry>
        </collision>
        <inertial>
            <mass value="0.01" />
            <inertia ixx="1e-3" ixy="0.0" ixz="0.0" iyy="1e-3" iyz="0.0" izz="1e-3" />
        </inertial>
    </link>

    <joint name="joint2" type="revolute">
        <parent link="link2" />
        <child link="link3" />
        <origin rpy="${link3_theta} 0 ${link3_alpha}" xyz="${link3_a} 0 ${link3_d}" />
        <limit lower="${-pi/2}" upper="${pi/2}" effort="100" velocity="1.0" />
        <axis xyz="0 0 1" />
    </joint> -->
  <!-- <ros2_control name="GazeboSystem" type="system">
        <hardware>
        <plugin>gazebo_ros2_control/GazeboSystem</plugin>
        </hardware>
        <joint name="joint1">
        <command_interface name="position" />
        <command_interface name="velocity" />
        <state_interface name="position"/>
        <state_interface name="velocity"/>
        </joint>
        <joint name="joint2">
        <command_interface name="position" />
        <command_interface name="velocity" />
        <state_interface name="position"/>
        <state_interface name="velocity"/>
        </joint>
    </ros2_control> -->
  <!-- <gazebo>
        <plugin filename="libgazebo_ros2_control.so" name="gazebo_ros2_control">
        <parameters>$(find assign1)/config/joints.yaml</parameters>
        </plugin>
    </gazebo> -->
</robot>
