<?xml version="1.0" ?>
<!-- =================================================================================== -->
<!-- |    This document was autogenerated by xacro from scara.urdf.xacro               | -->
<!-- |    EDITING THIS FILE BY HAND IS NOT RECOMMENDED                                 | -->
<!-- =================================================================================== -->
<robot name="scara_robot">
  <!-- <xacro:property name="link1_arm_theta" value="0" />
    <xacro:property name="link1_arm_d" value="${link1_l}" />
    <xacro:property name="link1_arm_a" value="0" />
    <xacro:property name="link1_arm_alpha" value="0" /> -->
  <link name="world_link"/>
  <joint name="world_to_base" type="fixed">
    <parent link="world_link"/>
    <child link="base_link"/>
    <origin rpy="0 0 0" xyz="0 0 0"/>
  </joint>
  <link name="base_link">
    <visual>
      <origin rpy="0 0 0" xyz="0 0 0.05"/>
      <geometry>
        <box size="0.5 0.5 0.1"/>
      </geometry>
    </visual>
    <collision>
      <origin rpy="0 0 0" xyz="0 0 0.05"/>
      <geometry>
        <box size="0.5 0.5 0.1"/>
      </geometry>
    </collision>
    <inertial>
      <origin rpy="0 0 0" xyz="0 0 0.05"/>
      <mass value="10"/>
      <inertia ixx="0.21666666666666665" ixy="0.0" ixz="0.0" iyy="0.21666666666666665" iyz="0.0" izz="0.41666666666666663"/>
    </inertial>
  </link>
  <joint name="joint1" type="revolute">
    <parent link="base_link"/>
    <child link="link1"/>
    <origin rpy="0 0 0" xyz="0 0 0.1"/>
    <axis xyz="0 0 1"/>
    <limit effort="100" lower="-2.6179938779914944" upper="2.6179938779914944" velocity="5.0"/>
    <dynamics damping="0.1" friction="0.1"/>
  </joint>
  <link name="link1">
    <visual>
      <origin rpy="0 0 0" xyz="0 0 0.3"/>
      <geometry>
        <cylinder length="0.6" radius="0.1"/>
      </geometry>
    </visual>
    <collision>
      <origin rpy="0 0 0" xyz="0 0 0.3"/>
      <geometry>
        <cylinder length="0.6" radius="0.1"/>
      </geometry>
    </collision>
    <inertial>
      <origin rpy="0 0 0" xyz="0 0 0.3"/>
      <mass value="0.01"/>
      <inertia ixx="0.000325" ixy="0.0" ixz="0.0" iyy="0.000325" iyz="0.0" izz="5.000000000000001e-05"/>
    </inertial>
    <visual>
      <origin rpy="0 0 0" xyz="0.3 0 0.6"/>
      <geometry>
        <box size="0.6 0.2 0.1"/>
      </geometry>
    </visual>
    <collision>
      <origin rpy="0 0 0" xyz="0.3 0 0.6"/>
      <geometry>
        <box size="0.39999999999999997 0.2 0.1"/>
      </geometry>
    </collision>
    <inertial>
      <origin rpy="0 0 0" xyz="0.3 0 0"/>
      <mass value="0.01"/>
      <inertia ixx="4.166666666666667e-05" ixy="0.0" ixz="0.0" iyy="0.0003083333333333333" iyz="0.0" izz="0.0003333333333333333"/>
    </inertial>
  </link>
  <link name="link2">
    <visual>
      <origin rpy="0 0 0" xyz="0 0 0"/>
      <geometry>
        <cylinder length="0.2" radius="0.1"/>
      </geometry>
    </visual>
    <collision>
      <origin rpy="0 0 0" xyz="0 0 0"/>
      <geometry>
        <cylinder length="0.2" radius="0.1"/>
      </geometry>
    </collision>
    <inertial>
      <origin rpy="0 0 0" xyz="0 0 0"/>
      <mass value="0.01"/>
      <inertia ixx="5.833333333333333e-05" ixy="0.0" ixz="0.0" iyy="5.833333333333333e-05" iyz="0.0" izz="5.000000000000001e-05"/>
    </inertial>
    <visual>
      <origin rpy="0 0 0" xyz="0.3 0 0"/>
      <geometry>
        <box size="0.6 0.2 0.1"/>
      </geometry>
    </visual>
    <collision>
      <origin rpy="0 0 0" xyz="0.3 0 0"/>
      <geometry>
        <box size="0.39999999999999997 0.2 0.1"/>
      </geometry>
    </collision>
    <inertial>
      <origin rpy="0 0 0" xyz="0.3 0 0"/>
      <mass value="0.01"/>
      <inertia ixx="4.166666666666667e-05" ixy="0.0" ixz="0.0" iyy="0.0003083333333333333" iyz="0.0" izz="0.0003333333333333333"/>
    </inertial>
  </link>
  <joint name="joint2" type="revolute">
    <parent link="link1"/>
    <child link="link2"/>
    <origin rpy="0 0 0" xyz="0.6 0 0.6"/>
    <limit effort="100" lower="-1.5707963267948966" upper="1.5707963267948966" velocity="1.0"/>
    <axis xyz="0 0 1"/>
  </joint>
  <link name="link3">
    <visual>
      <origin rpy="0 0 0" xyz="0 0 0.15"/>
      <geometry>
        <box size="0.2 0.2 0.5"/>
      </geometry>
    </visual>
    <collision>
      <origin rpy="0 0 0" xyz="0 0 0.15"/>
      <geometry>
        <box size="0.2 0.2 0.5"/>
      </geometry>
    </collision>
    <inertial>
      <origin rpy="0 0 0" xyz="0 0 0.15"/>
      <mass value="0.01"/>
      <inertia ixx="0.00024166666666666667" ixy="0.0" ixz="0.0" iyy="0.00024166666666666667" iyz="0.0" izz="6.666666666666667e-05"/>
    </inertial>
  </link>
  <joint name="joint3" type="prismatic">
    <parent link="link2"/>
    <child link="link3"/>
    <origin rpy="0 0 0" xyz="0.6 0 0"/>
    <limit effort="100" lower="0" upper="0.3" velocity="5"/>
    <axis xyz="0 0 -1"/>
  </joint>
  <link name="link4">
    <visual>
      <origin rpy="0 0 0" xyz="0 0 -0.15"/>
      <geometry>
        <cylinder length="0.3" radius="0.05"/>
      </geometry>
    </visual>
    <collision>
      <origin rpy="0 0 0" xyz="0 0 -0.09999999999999999"/>
      <geometry>
        <cylinder length="0.19999999999999998" radius="0.05"/>
      </geometry>
    </collision>
    <inertial>
      <origin rpy="0 0 0" xyz="0 0 -0.15"/>
      <mass value="0.01"/>
      <inertia ixx="8.125e-05" ixy="0.0" ixz="0.0" iyy="8.125e-05" iyz="0.0" izz="1.2500000000000002e-05"/>
    </inertial>
  </link>
  <joint name="joint4" type="fixed">
    <parent link="link3"/>
    <child link="link4"/>
    <origin rpy="3.141592653589793 0 0" xyz="0 0 -0.3"/>
    <axis xyz="0 0 1"/>
  </joint>
  <!-- Use for GUI control -->
  <!-- <gazebo>
        <plugin filename="gz-sim-joint-position-controller-system"
            name="gz::sim::systems::JointPositionController">
            <joint_name>joint1</joint_name>
            <use_velocity_commands>true</use_velocity_commands>
            <cmd_max>1.0</cmd_max>
        </plugin>

        <plugin filename="gz-sim-joint-position-controller-system"
            name="gz::sim::systems::JointPositionController">
            <joint_name>joint2</joint_name>
            <use_velocity_commands>true</use_velocity_commands>
            <cmd_max>1.0</cmd_max>
        </plugin>

        <plugin filename="gz-sim-joint-position-controller-system"
            name="gz::sim::systems::JointPositionController">
            <joint_name>joint3</joint_name>
            <use_velocity_commands>true</use_velocity_commands>
            <cmd_max>1.0</cmd_max>
        </plugin>         
    </gazebo> -->
  <gazebo>
    <plugin filename="gz-sim-joint-state-publisher-system" name="gz::sim::systems::JointStatePublisher">
      <topic>/joint_states</topic>
    </plugin>
    <plugin filename="gz-sim-pose-publisher-system" name="gz::sim::systems::PosePublisher">
      <publish_link_pose>true</publish_link_pose>
      <publish_sensor_pose>false</publish_sensor_pose>
      <publish_collision_pose>false</publish_collision_pose>
      <publish_visual_pose>false</publish_visual_pose>
      <publish_nested_model_pose>false</publish_nested_model_pose>
      <use_pose_vector_msg>true</use_pose_vector_msg>
    </plugin>
    <plugin filename="ignition-gazebo-joint-trajectory-controller-system" name="ignition::gazebo::systems::JointTrajectoryController">
      <topic>/model/scara_robot/joint_trajectory</topic>
      <joint_name>joint1</joint_name>
      <joint_name>joint2</joint_name>
      <joint_name>joint3</joint_name>
      <initial_position>0.0</initial_position>
      <initial_position>0.0</initial_position>
      <initial_position>0.0</initial_position>
      <position_p_gain>20</position_p_gain>
      <position_p_gain>20</position_p_gain>
      <position_p_gain>20</position_p_gain>
      <position_i_gain>0.0</position_i_gain>
      <position_i_gain>0.0</position_i_gain>
      <position_i_gain>0.0</position_i_gain>
      <position_d_gain>1.0</position_d_gain>
      <position_d_gain>1.0</position_d_gain>
      <position_d_gain>1.0</position_d_gain>
      <position_i_min>-1</position_i_min>
      <position_i_min>-1</position_i_min>
      <position_i_min>-1</position_i_min>
      <position_i_max>1</position_i_max>
      <position_i_max>1</position_i_max>
      <position_i_max>1</position_i_max>
      <position_cmd_min>-50</position_cmd_min>
      <position_cmd_min>-50</position_cmd_min>
      <position_cmd_min>-50</position_cmd_min>
      <position_cmd_max>50</position_cmd_max>
      <position_cmd_max>50</position_cmd_max>
      <position_cmd_max>50</position_cmd_max>
    </plugin>
  </gazebo>
</robot>
