<?xml version="1.0" ?>
<!-- =================================================================================== -->
<!-- |    This document was autogenerated by xacro from ./src/assign3/urdf/scara_fixed_joints.urdf.xacro | -->
<!-- |    EDITING THIS FILE BY HAND IS NOT RECOMMENDED                                 | -->
<!-- =================================================================================== -->
<robot name="scara_robot">
  <!-- Joint colors-->
  <material name="blue">
    <color rgba="0 0 0.8 1"/>
  </material>
  <material name="red">
    <color rgba="0.8 0 0 1"/>
  </material>
  <material name="green">
    <color rgba="0.0 1.0 0.0 1.0"/>
  </material>
  <material name="purple">
    <color rgba="0.5 0.0 0.5 1.0"/>
  </material>
  <!-- 
            Model setup 
    -->
  <!-- 
            Modeling the robot
    -->
  <link name="world_link"/>
  <joint name="world_to_base" type="fixed">
    <parent link="world_link"/>
    <child link="base_link"/>
    <origin rpy="0 0 0" xyz="0 0 0"/>
  </joint>
  <link name="base_link">
    <visual>
      <origin rpy="0 0 0" xyz="0 0 0.05"/>
      <geometry>
        <box size="0.5 0.5 0.1"/>
      </geometry>
    </visual>
    <collision>
      <origin rpy="0 0 0" xyz="0 0 0.05"/>
      <geometry>
        <box size="0.5 0.5 0.1"/>
      </geometry>
    </collision>
    <inertial>
      <origin rpy="0 0 0" xyz="0 0 0.05"/>
      <mass value="100"/>
      <inertia ixx="2.1666666666666665" ixy="0.0" ixz="0.0" iyy="2.1666666666666665" iyz="0.0" izz="4.166666666666666"/>
    </inertial>
  </link>
  <joint name="joint1" type="revolute">
    <parent link="base_link"/>
    <child link="link1"/>
    <origin rpy="0 0 0" xyz="0 0 0"/>
    <axis xyz="0 0 1"/>
    <limit effort="100" lower="-2.748893571891069" upper="2.748893571891069" velocity="5.0"/>
    <dynamics damping="0.1" friction="0.0"/>
  </joint>
  <link name="link1">
    <!-- Cylinder joint visual -->
    <visual>
      <origin rpy="0 0 0" xyz="0 0 0.25"/>
      <geometry>
        <cylinder length="0.5" radius="0.1"/>
      </geometry>
      <material name="green"/>
    </visual>
    <collision>
      <origin rpy="0 0 0" xyz="0 0 0.3"/>
      <geometry>
        <cylinder length="0.4" radius="0.1"/>
      </geometry>
    </collision>
    <inertial>
      <origin rpy="0 0 0" xyz="0 0 0.25"/>
      <mass value="10"/>
      <inertia ixx="0.23333333333333334" ixy="0.0" ixz="0.0" iyy="0.23333333333333334" iyz="0.0" izz="0.05000000000000001"/>
    </inertial>
    <!-- Arm visual -->
    <visual>
      <origin rpy="0 0 0" xyz="0.225 0 0.5"/>
      <geometry>
        <box size="0.45 0.1 0.1"/>
      </geometry>
    </visual>
    <collision>
      <origin rpy="0 0 0" xyz="0.225 0 0.5"/>
      <geometry>
        <box size="0.25 0.1 0.1"/>
      </geometry>
    </collision>
    <inertial>
      <origin rpy="0 0 0" xyz="0.225 0 0"/>
      <mass value="5"/>
      <inertia ixx="0.008333333333333335" ixy="0.0" ixz="0.0" iyy="0.08854166666666667" iyz="0.0" izz="0.08854166666666667"/>
    </inertial>
  </link>
  <link name="link2">
    <!-- Cylinder joint  visual -->
    <visual>
      <origin rpy="0 0 0" xyz="0 0 0"/>
      <geometry>
        <cylinder length="0.2" radius="0.1"/>
      </geometry>
      <material name="blue"/>
    </visual>
    <collision>
      <origin rpy="0 0 0" xyz="0 0 0"/>
      <geometry>
        <cylinder length="0.2" radius="0.1"/>
      </geometry>
    </collision>
    <inertial>
      <origin rpy="0 0 0" xyz="0 0 0"/>
      <mass value="5"/>
      <inertia ixx="0.029166666666666667" ixy="0.0" ixz="0.0" iyy="0.029166666666666667" iyz="0.0" izz="0.025000000000000005"/>
    </inertial>
    <!-- Arm visual -->
    <visual>
      <origin rpy="0 0 0" xyz="0.175 0 0"/>
      <geometry>
        <box size="0.35 0.1 0.1"/>
      </geometry>
    </visual>
    <collision>
      <origin rpy="0 0 0" xyz="0.175 0 0"/>
      <geometry>
        <box size="0.14999999999999997 0.1 0.1"/>
      </geometry>
    </collision>
    <inertial>
      <origin rpy="0 0 0" xyz="0.175 0 0"/>
      <mass value="5"/>
      <inertia ixx="0.008333333333333335" ixy="0.0" ixz="0.0" iyy="0.05520833333333332" iyz="0.0" izz="0.05520833333333332"/>
    </inertial>
  </link>
  <joint name="joint2" type="revolute">
    <parent link="link1"/>
    <child link="link2"/>
    <origin rpy="0 0 0" xyz="0.45 0 0.5"/>
    <limit effort="100" lower="-2.0943951023931953" upper="2.0943951023931953" velocity="1.0"/>
    <axis xyz="0 0 1"/>
    <dynamics damping="1" friction="0"/>
  </joint>
  <link name="link3">
    <!-- Prismatic joint visual -->
    <visual>
      <origin rpy="0 0 0" xyz="0 0 0.1"/>
      <geometry>
        <box size="0.2 0.2 0.4"/>
      </geometry>
      <material name="red"/>
    </visual>
    <collision>
      <origin rpy="0 0 0" xyz="0 0 0.1"/>
      <geometry>
        <box size="0.2 0.2 0.4"/>
      </geometry>
    </collision>
    <inertial>
      <origin rpy="0 0 0" xyz="0 0 0.1"/>
      <mass value="10"/>
      <inertia ixx="0.16666666666666669" ixy="0.0" ixz="0.0" iyy="0.16666666666666669" iyz="0.0" izz="0.06666666666666668"/>
    </inertial>
  </link>
  <joint name="joint3" type="prismatic">
    <parent link="link2"/>
    <child link="link3"/>
    <origin rpy="0 0 0" xyz="0.35 0 0"/>
    <axis xyz="0 0 -1"/>
    <limit effort="1000" lower="0" upper="0.2" velocity="5"/>
    <dynamics damping="1" friction="0"/>
  </joint>
  <link name="link4">
    <!-- Cylinder visual -->
    <visual>
      <origin rpy="0 0 0" xyz="0 0 -0.15"/>
      <geometry>
        <cylinder length="0.3" radius="0.05"/>
      </geometry>
      <material name="purple"/>
    </visual>
    <collision>
      <origin rpy="0 0 0" xyz="0 0 -0.09999999999999999"/>
      <geometry>
        <cylinder length="0.19999999999999998" radius="0.05"/>
      </geometry>
    </collision>
    <inertial>
      <origin rpy="0 0 0" xyz="0 0 -0.15"/>
      <mass value="1"/>
      <inertia ixx="0.008125" ixy="0.0" ixz="0.0" iyy="0.008125" iyz="0.0" izz="0.0012500000000000002"/>
    </inertial>
  </link>
  <joint name="joint4" type="fixed">
    <parent link="link3"/>
    <child link="link4"/>
    <origin rpy="3.141592653589793 0 0" xyz="0 0 -0.3"/>
    <axis xyz="0 0 1"/>
  </joint>
  <!-- 
            Gazebo configuration 
     -->
  <!-- 
        Use for GUI control, 
        comment out for control via ros2 trajectory
    -->
  <gazebo>
    <!-- <plugin filename="gz-sim-joint-position-controller-system"
            name="gz::sim::systems::JointPositionController">
            <joint_name>joint1</joint_name>
            <use_velocity_commands>true</use_velocity_commands>
            <cmd_max>1.0</cmd_max>
        </plugin>

        <plugin filename="gz-sim-joint-position-controller-system"
            name="gz::sim::systems::JointPositionController">
            <joint_name>joint2</joint_name>
            <use_velocity_commands>true</use_velocity_commands>
            <cmd_max>1.0</cmd_max>
        </plugin> -->
    <!-- <plugin filename="gz-sim-joint-position-controller-system"
            name="gz::sim::systems::JointPositionController">
            <joint_name>joint3</joint_name>
            <use_velocity_commands>true</use_velocity_commands>
            <cmd_max>1.0</cmd_max>
        </plugin>          -->
  </gazebo>
  <!-- Set joint4 to publish, it is fixed joint which will not publish by default-->
  <!-- <gazebo reference="joint4">
        <preserveFixedJoint>true</preserveFixedJoint>
    </gazebo> -->
  <gazebo>
    <plugin filename="gz-sim-joint-state-publisher-system" name="gz::sim::systems::JointStatePublisher">
      <topic>/joint_states</topic>
    </plugin>
    <plugin filename="gz-sim-apply-joint-force-system" name="gz::sim::systems::ApplyJointForce">
      <joint_name>joint1</joint_name>
    </plugin>
    <plugin filename="gz-sim-apply-joint-force-system" name="gz::sim::systems::ApplyJointForce">
      <joint_name>joint2</joint_name>
    </plugin>
    <plugin filename="gz-sim-apply-joint-force-system" name="gz::sim::systems::ApplyJointForce">
      <joint_name>joint3</joint_name>
    </plugin>
    <plugin filename="gz-sim-pose-publisher-system" name="gz::sim::systems::PosePublisher">
      <publish_link_pose>true</publish_link_pose>
      <publish_model_pose>true</publish_model_pose>
      <publish_sensor_pose>false</publish_sensor_pose>
      <publish_collision_pose>false</publish_collision_pose>
      <publish_visual_pose>false</publish_visual_pose>
      <publish_nested_model_pose>false</publish_nested_model_pose>
      <use_pose_vector_msg>true</use_pose_vector_msg>
    </plugin>
  </gazebo>
</robot>
